Workbook
Name IQ_CH: 110000
Name IQ_CQ: 5000
Name IQ_CY: 10000
Name IQ_DAILY: 500000
Name IQ_FH: 100000
Name IQ_FQ: 500
Name IQ_FY: 1000
Name IQ_LTM: 2000
Name IQ_MONTH: 15000
Name IQ_NTM: 6000
Name IQ_WEEK: 50000
Name IQ_YTD: 3000

Sheet Summary
A1: CATALYST PHARMACEUTICALS (CPRX) – LBO MODEL SUMMARY
A2: Source: S&P Capital IQ | All figures in $000s | Prepared: March 2026
A4: ▌ KEY DEAL METRICS
A5: Metric | B5: Value | D5: Metric | E5: Value
A6: Entry EV/EBITDA | B6: ='Transaction Assumptions'!B9 -> 9.45 | D6: Exit EV/EBITDA (Base) | E6: ='Returns Analysis'!E6 -> 12
A7: Entry EV ($000) | B7: ='Transaction Assumptions'!B10 -> 2793901.9 | D7: Exit EV ($000, Base) | E7: ='Returns Analysis'!E8 -> 7037639.1
A8: Sponsor Equity ($000) | B8: ='Transaction Assumptions'!B23 -> 664262.95 | D8: Equity Proceeds ($000, Base) | E8: ='Returns Analysis'!E10 -> 8082647.8
A9: Total Debt at Entry ($000) | B9: =5*'Transaction Assumptions'!B7 -> 1478255 | D9: MOIC (Base) | E9: ='Returns Analysis'!E15 -> 12.167844
A10: Entry Leverage (x) | B10: =B9/'Transaction Assumptions'!B7 -> 5 | D10: IRR (Base) | E10: ='Returns Analysis'!E16 -> 0.64832454
E11: ='Returns Analysis'!E16 -> 0.64832454
A12: ▌ PROJECTED FINANCIALS SNAPSHOT
A13: Metric ($000) | B13: 2026E | C13: 2027E | D13: 2028E | E13: 2029E | F13: 2030E
A14: Revenue | B14: ='Levered FCFs'!G6 -> 659667.68 | C14: ='Levered FCFs'!H6 -> 738827.8 | D14: ='Levered FCFs'!I6 -> 827487.14 | E14: ='Levered FCFs'!J6 -> 926785.59 | F14: ='Levered FCFs'!K6 -> 1037999.9
A15: EBITDA | B15: ='Levered FCFs'!G18 -> 372712.24 | C15: ='Levered FCFs'!H18 -> 417437.71 | D15: ='Levered FCFs'!I18 -> 467530.23 | E15: ='Levered FCFs'!J18 -> 523633.86 | F15: ='Levered FCFs'!K18 -> 586469.92
A16: EBITDA Margin | B16: =IFERROR('Levered FCFs'!G18/'Levered FCFs'!G6,0) -> 0.565 | C16: =IFERROR('Levered FCFs'!H18/'Levered FCFs'!H6,0) -> 0.565 | D16: =IFERROR('Levered FCFs'!I18/'Levered FCFs'!I6,0) -> 0.565 | E16: =IFERROR('Levered FCFs'!J18/'Levered FCFs'!J6,0) -> 0.565 | F16: =IFERROR('Levered FCFs'!K18/'Levered FCFs'!K6,0) -> 0.565
A17: LFCF | B17: ='Levered FCFs'!G31 -> 321717.14 | C17: ='Levered FCFs'!H31 -> 424389.35 | D17: ='Levered FCFs'!I31 -> 489017.97 | E17: ='Levered FCFs'!J31 -> 554341.34 | F17: ='Levered FCFs'!K31 -> 627752.27
A18: Total Debt | B18: ='Capital Structure'!C22 -> 987799.56 | C18: ='Capital Structure'!D22 -> 1100112.4 | D18: ='Capital Structure'!E22 -> 1225195.1 | E18: ='Capital Structure'!F22 -> 1364499.8 | F18: ='Capital Structure'!G22 -> 1519643.5
A19: Net Leverage (x) | B19: ='Capital Structure'!C24 -> 2.6503008 | C19: ='Capital Structure'!D24 -> 2.6353929 | D19: ='Capital Structure'!E24 -> 2.6205688 | E19: ='Capital Structure'!F24 -> 2.6058281 | F19: ='Capital Structure'!G24 -> 2.5911703
A21: ▌ MODEL NAVIGATION
A22: Transaction Assumptions | B22: Transaction assumptions, S&U, Debt Terms, Operating Drivers
A23: Levered FCFs | B23: Income Statement Projections & Levered Free Cash Flow build
A24: Capital Structure | B24: Debt schedule: Revolver, TLB, PIK, Cash Sweep
A25: Returns Analysis | B25: MOIC, IRR, and Sensitivity tables
A26: Value Creation | B26: Value Creation Bridge & Equity Waterfall
A29: ▌ COLOR LEGEND
A30: Blue text | B30: Hardcoded Inputs / Assumptions (Changeable)
A31: Black text | B31: Formulas & Calculations (Do Not Overwrite)
A32: Green text | B32: Cross-Sheet Linked Formulas
A33: Yellow highlight | B33: Key Assumptions Needing Attention
A34: Green background | B34: Key Outputs / Totals

Sheet Transaction Assumptions
A1: CPRX – LBO MODEL | Transaction Assumptions
A2: All figures in $000s unless otherwise noted | Source: S&P Capital IQ
A4: ▌ ENTRY VALUATION
A5: Entry Date | B5: 12/31/2025 | D5: Acquisition closing date
A6: LTM Revenue ($000) | B6: 588989 | D6: Source: S&P CIQ 2025 FY
A7: LTM EBITDA ($000) | B7: 295651 | D7: Source: S&P CIQ 2025 FY
A8: LTM EBITDA Margin | B8: =B7/B6 -> 0.50196353 | D8: Calculated
A9: Entry EV/EBITDA Multiple | B9: =9.45 -> 9.45 | D9: Entry multiple assumption
A10: Enterprise Value ($000) | B10: =B7*B9 -> 2793901.9 | D10: EV = EBITDA × Entry Multiple
A11: (+) Cash on Balance Sheet ($000) | B11: 709171 | D11: Source: S&P CIQ 2025 FY
A12: (−) Total Debt at Close ($000) | B12: 2787 | D12: Source: S&P CIQ 2025 FY
A13: Equity Value (implied) ($000) | B13: =B10+B11-B12 -> 3500285.9 | D13: EV + Cash − Debt
A14: Shares Outstanding (000s) | B14: 122514 | D14: Source: S&P CIQ 2025 FY
A15: Implied Price per Share ($) | B15: =B13/B14 -> 28.570498
A17: ▌ SOURCES & USES OF FUNDS
A18: Sources ($000) | B18: Amount | D18: Uses ($000) | E18: Amount
A19: Revolver (drawn at close) | B19: 0 | D19: Enterprise Value (Purchase Price) | E19: =B10 -> 2793901.9
A20: Cash on Balance Sheet at the FYE | B20: =B11 -> 709171 | D20: Refinancing Existing Debt | E20: =B12 -> 2787
A21: Term Loan B | B21: =Summary!B9*2/5 -> 591302 | D21: Minimum Cash Balance | E21: 40000
A22: PIK Loan | B22: =Summary!B9*3/5 -> 886953 | D22: Transaction Fees & Expenses | E22: 15000
A23: Sponsor Equity | B23: =E23-B19-B20-B21-B22 -> 664262.95 | D23: Total Uses | E23: =SUM(E19:E22) -> 2851688.9
A24: Total Sources | B24: =SUM(B19:B23) -> 2851688.9
A26: ▌ OPERATING ASSUMPTIONS (Projection Period)
A27: Assumption | B27: Value | C27: Notes
A28: Revenue Growth Rate (YoY) | B28: 0.12 | C28: Growth applied to LTM Revenue
A29: Gross Margin % | B29: 0.83 | C29: Based on 2025A: 489,027/588,989
A30: SG&A as % of Revenue | B30: 0.329 | C30: Based on 2025A: 193,751/588,989
A31: D&A as % of Revenue | B31: 0.064 | C31: Based on 2025A: 37,873/588,989
A32: CapEx as % of Revenue | B32: 0.005 | C32: Normalized; 2025A minimal
A33: Cash Tax Rate | B33: 0.244 | C33: Effective rate 2025A
A34: Change in NWC as % of Revenue | B34: 0.025 | C34: Avg 2023-2025 NWC build
A35: Amortization of Intangibles ($000) | B35: 37498 | C35: Constant from 2025 level
A36: Stock-Based Compensation ($000) | B36: 24778 | C36: 2025A level (non-cash add-back)
A37: SOFR | B37: 0.04 | C37: 2027 Expectation
A38: ▌ DEBT ASSUMPTIONS
A39: Tranche | B39: Principal ($000) | C39: Interest Rate | D39: Amort/PIK % | E39: Notes
A40: Revolver | B40: =B7*0.93015 -> 274999.78 | C40: =7.5% -> 0.075 | D40: 0 | E40: Commitment; drawn as needed
A41: Term Loan B | B41: =B21 -> 591302 | C41: =3.87%+3.75% -> 0.0762 | D41: 0.05 | E41: 5% annual amortization
A42: PIK Loan | B42: =B22 -> 886953 | C42: =3.87%+7.5% -> 0.1137 | D42: 1 | E42: 100% PIK (accrues to principal)
A43: Cash Floor (Min Balance $000) | B43: =E21 -> 40000 | E43: Minimum cash maintained
...

Sheet Levered FCFs
A1: CPRX – Levered Free Cash Flow Projections
A2: All figures in $000s | Fiscal Year Ending December 31
B4: 2021A | C4: 2022A | D4: 2023A | E4: 2024A | F4: 2025A | G4: 2026E | H4: 2027E | I4: 2028E | J4: 2029E | K4: 2030E
A5: ▌ INCOME STATEMENT
A6: Revenue | B6: 140833 | C6: 214203 | D6: 398204 | E6: 491734 | F6: 588989 | G6: =F6*(1+'Returns Analysis'!$K$21) -> 659667.68 | H6: =G6*(1+'Returns Analysis'!$K$21) -> 738827.8 | I6: =H6*(1+'Returns Analysis'!$K$21) -> 827487.14 | J6: =I6*(1+'Returns Analysis'!$K$21) -> 926785.59 | K6: =J6*(1+'Returns Analysis'!$K$21) -> 1037999.9
A7: Cost of Goods Sold | B7: -38820 | C7: -54182 | D7: -145117 | E7: -81493 | F7: -99962 | G7: =-(G6*(1-'Transaction Assumptions'!B29)) -> -112143.51 | H7: =-(H6*(1-'Transaction Assumptions'!B29)) -> -125600.73 | I7: =-(I6*(1-'Transaction Assumptions'!B29)) -> -140672.81 | J7: =-(J6*(1-'Transaction Assumptions'!B29)) -> -157553.55 | K7: =-(K6*(1-'Transaction Assumptions'!B29)) -> -176459.98
A8: Gross Profit | B8: 102013 | C8: 160021 | D8: 253087 | E8: 410241 | F8: 489027 | G8: =G6+G7 -> 547524.17 | H8: =H6+H7 -> 613227.08 | I8: =I6+I7 -> 686814.32 | J8: =J6+J7 -> 769232.04 | K8: =K6+K7 -> 861539.89
A9: SG&A Expense | B9: -49628 | C9: -57085 | D9: -133710 | E9: -177740 | F9: -193751 | G9: =-G6*'Transaction Assumptions'!B30 -> -217030.67 | H9: =-H6*'Transaction Assumptions'!B30 -> -243074.35 | I9: =-I6*'Transaction Assumptions'!B30 -> -272243.27 | J9: =-J6*'Transaction Assumptions'!B30 -> -304912.46 | K9: =-K6*'Transaction Assumptions'!B30 -> -341501.96
A10: Amortization of Intangibles | B10: 0 | C10: -1098 | D10: -32565 | E10: -37377 | F10: -37498 | G10: =-'Transaction Assumptions'!B35 -> -37498 | H10: =G10 -> -37498 | I10: =H10 -> -37498 | J10: =I10 -> -37498 | K10: =J10 -> -37498
A11: EBIT (Operating Income) | B11: 52385 | C11: 101838 | D11: 86812 | E11: 195124 | F11: 257778 | G11: =G8+G9+G10 -> 292995.51 | H11: =H8+H9+H10 -> 332654.73 | I11: =I8+I9+I10 -> 377073.06 | J11: =J8+J9+J10 -> 426821.58 | K11: =K8+K9+K10 -> 482539.93
A12: Interest Expense (linked → Capital Structure) | B12: 0 | C12: 0 | D12: 0 | E12: 0 | F12: 0 | G12: =-'Capital Structure'!C39 -> -123375.16 | H12: =-'Capital Structure'!D39 -> -112312.81 | I12: =-'Capital Structure'!E39 -> -125082.78 | J12: =-'Capital Structure'!F39 -> -139304.69 | K12: =-'Capital Structure'!G39 -> -155143.63
A13: Interest Income (linked → Capital Structure) | B13: 0 | C13: 0 | D13: 0 | E13: 0 | F13: 0 | G13: 0 | H13: =AVERAGE('Capital Structure'!C34,'Capital Structure'!D34)*'Transaction Assumptions'!B37 -> 27253.836 | I13: =AVERAGE('Capital Structure'!D34,'Capital Structure'!E34)*'Transaction Assumptions'!B37 -> 45521.983 | J13: =AVERAGE('Capital Structure'!E34,'Capital Structure'!F34)*'Transaction Assumptions'!B37 -> 66389.169 | K13: =AVERAGE('Capital Structure'!F34,'Capital Structure'!G34)*'Transaction Assumptions'!B37 -> 90031.041
A14: EBT (Earnings Before Tax) | B14: 0 | C14: 0 | D14: 0 | E14: 0 | F14: 0 | G14: =G11+G12 -> 169620.35 | H14: =H11+H12+H13 -> 247595.76 | I14: =I11+I12 -> 251990.28 | J14: =J11+J12 -> 287516.9 | K14: =K11+K12 -> 327396.3
A15: Cash Income Tax | B15: 13185 | C15: 21640 | D15: 23101 | E15: 52374 | F15: 69189 | G15: =-MAX(0,G14*'Transaction Assumptions'!B33) -> -41387.364 | H15: =-MAX(0,H14*'Transaction Assumptions'!B33) -> -60413.364 | I15: =-MAX(0,I14*'Transaction Assumptions'!B33) -> -61485.628 | J15: =-MAX(0,J14*'Transaction Assumptions'!B33) -> -70154.122 | K15: =-MAX(0,K14*'Transaction Assumptions'!B33) -> -79884.698
A16: Net Income | B16: 39482 | C16: 83079 | D16: 71410 | E16: 163889 | F16: 214326 | G16: =G14+G15 -> 128232.98 | H16: =H14+H15 -> 187182.39 | I16: =I14+I15 -> 190504.65 | J16: =J14+J15 -> 217362.77 | K16: =K14+K15 -> 247511.6
A17: ▌ EBITDA BRIDGE
A18: EBITDA | B18: 52577 | C18: 103077 | D18: 119693 | E18: 232898 | F18: 295651 | G18: =G11-G10+G6*'Transaction Assumptions'!B31 -> 372712.24 | H18: =H11-H10+H6*'Transaction Assumptions'!B31 -> 417437.71 | I18: =I11-I10+I6*'Transaction Assumptions'!B31 -> 467530.23 | J18: =J11-J10+J6*'Transaction Assumptions'!B31 -> 523633.86 | K18: =K11-K10+K6*'Transaction Assumptions'!B31 -> 586469.92
A19: (−) D&A | B19: -192 | C19: -1239 | D19: -32881 | E19: -37774 | F19: -37873 | G19: =-(G6*'Transaction Assumptions'!B31+'Transaction Assumptions'!B35) -> -79716.732 | H19: =-(H6*'Transaction Assumptions'!B31+'Transaction Assumptions'!B35) -> -84782.979 | I19: =-(I6*'Transaction Assumptions'!B31+'Transaction Assumptions'!B35) -> -90457.177 | J19: =-(J6*'Transaction Assumptions'!B31+'Transaction Assumptions'!B35) -> -96812.278 | K19: =-(K6*'Transaction Assumptions'!B31+'Transaction Assumptions'!B35) -> -103929.99
A20: EBIT (check) | B20: 52385 | C20: 101838 | D20: 86812 | E20: 195124 | F20: 257778 | G20: =G18+G19 -> 292995.51 | H20: =H18+H19 -> 332654.73 | I20: =I18+I19 -> 377073.06 | J20: =J18+J19 -> 426821.58 | K20: =K18+K19 -> 482539.93
A21: ▌ LEVERED FREE CASH FLOW
A22: EBITDA | B22: 52577 | C22: 103077 | D22: 119693 | E22: 232898 | F22: 295651 | G22: =G18 -> 372712.24 | H22: =H18 -> 417437.71 | I22: =I18 -> 467530.23 | J22: =J18 -> 523633.86 | K22: =K18 -> 586469.92
A23: (+) Cash Interest Income | B23: 0 | C23: 0 | D23: 0 | E23: 0 | F23: 0 | G23: 0 | H23: =H13 -> 27253.836 | I23: =I13 -> 45521.983 | J23: =J13 -> 66389.169 | K23: =K13 -> 90031.041
A24: (−) Cash Interest Expense | B24: 0 | C24: 0 | D24: 705 | E24: 1395 | F24: 466 | G24: =-'Capital Structure'!C37 -> -22528.606 | H24: =-'Capital Structure'!D37 -> 0 | I24: =-'Capital Structure'!E37 -> 0 | J24: =-'Capital Structure'!F37 -> 0 | K24: =-'Capital Structure'!G37 -> 0
A25: (−) Cash Taxes | B25: 3000 | C25: 7667 | D25: 50458 | E25: 68451 | F25: 71986 | G25: =G15 -> -41387.364 | H25: =H15 -> -60413.364 | I25: =I15 -> -61485.628 | J25: =J15 -> -70154.122 | K25: =K15 -> -79884.698
A26: (−) Capital Expenditures | B26: -1021 | C26: -10029 | D26: -198524 | E26: -556 | F26: -58 | G26: =-G6*'Transaction Assumptions'!B32 -> -3298.3384 | H26: =-H6*'Transaction Assumptions'!B32 -> -3694.139 | I26: =-I6*'Transaction Assumptions'!B32 -> -4137.4357 | J26: =-J6*'Transaction Assumptions'!B32 -> -4633.928 | K26: =-K6*'Transaction Assumptions'!B32 -> -5189.9993
A27: (±) Change in Net Working Capital | B27: 4154 | C27: 26925 | D27: -40839 | E27: 20219 | F27: -52364 | G27: =-G6*'Transaction Assumptions'!B34 -> -16491.692 | H27: =-H6*'Transaction Assumptions'!B34 -> -18470.695 | I27: =-I6*'Transaction Assumptions'!B34 -> -20687.178 | J27: =-J6*'Transaction Assumptions'!B34 -> -23169.64 | K27: =-K6*'Transaction Assumptions'!B34 -> -25949.997
A28: (+) Stock-Based Compensation (non-cash) | B28: 6073 | C28: 7907 | D28: 14250 | E28: 22251 | F28: 24778 | G28: ='Transaction Assumptions'!B36 -> 24778 | H28: ='Transaction Assumptions'!B36 -> 24778 | I28: ='Transaction Assumptions'!B36 -> 24778 | J28: ='Transaction Assumptions'!B36 -> 24778 | K28: ='Transaction Assumptions'!B36 -> 24778
A29: (+) Amortization of Intangibles (non-cash) | B29: 0 | C29: 1098 | D29: 32565 | E29: 37377 | F29: 37498 | G29: ='Transaction Assumptions'!B35 -> 37498 | H29: ='Transaction Assumptions'!B35 -> 37498 | I29: ='Transaction Assumptions'!B35 -> 37498 | J29: ='Transaction Assumptions'!B35 -> 37498 | K29: ='Transaction Assumptions'!B35 -> 37498
A30: (−) Mandatory Debt Amortization | B30: 0 | C30: 0 | D30: 0 | E30: 0 | F30: 0 | G30: ='Capital Structure'!C13 -> -29565.1 | H30: ='Capital Structure'!D13 -> 0 | I30: ='Capital Structure'!E13 -> 0 | J30: ='Capital Structure'!F13 -> 0 | K30: ='Capital Structure'!G13 -> 0
A31: Levered Free Cash Flow (LFCF) | B31: 42139 | C31: 89691 | D31: -219488 | E31: 201641 | F31: 171340 | G31: =G22+G23+G24+G25+G26+G27+G28+G29+G30 -> 321717.14 | H31: =H22+H23+H24+H25+H26+H27+H28+H29+H30 -> 424389.35 | I31: =I22+I23+I24+I25+I26+I27+I28+I29+I30 -> 489017.97 | J31: =J22+J23+J24+J25+J26+J27+J28+J29+J30 -> 554341.34 | K31: =K22+K23+K24+K25+K26+K27+K28+K29+K30 -> 627752.27
A32: (+) Beginning of Period Cash Balance | B32: 0 | C32: 0 | D32: 0 | E32: 0 | F32: 0 | G32: ='Capital Structure'!C28 -> 709171 | H32: ='Capital Structure'!D28 -> 469151.24 | I32: ='Capital Structure'!E28 -> 893540.58 | J32: ='Capital Structure'!F28 -> 1382558.6 | K32: ='Capital Structure'!G28 -> 1936899.9
A33: (−) Minimum Cash Balance | B33: 0 | C33: 0 | D33: 0 | E33: 0 | F33: 0 | G33: =-'Transaction Assumptions'!E21 -> -40000 | H33: =G33 -> -40000 | I33: =H33 -> -40000 | J33: =I33 -> -40000 | K33: =J33 -> -40000
A34: Excess Cash Flow Available for Debt Repayment | B34: 0 | C34: 0 | D34: 0 | E34: 0 | F34: 0 | G34: =G31+G32+G33 -> 990888.14 | H34: =H31+H32+H33 -> 853540.58 | I34: =I31+I32+I33 -> 1342558.6 | J34: =J31+J32+J33 -> 1896899.9 | K34: =K31+K32+K33 -> 2524652.2

Sheet Capital Structure
A1: CPRX – Capital Structure & Debt Schedule
A2: All figures in $000s | Fiscal Year Ending December 31
B4: 2025A (Entry) | C4: 2026E | D4: 2027E | E4: 2028E | F4: 2029E | G4: 2030E
A5: ▌ REVOLVER
A6: Revolver – Beginning Balance | B6: 0 | C6: =0 -> 0 | D6: =C9 -> 0 | E6: =D9 -> 0 | F6: =E9 -> 0 | G6: =F9 -> 0
A7: (+) Revolver Draws | B7: 0 | C7: 0 | D7: 0 | E7: 0 | F7: 0 | G7: 0
A8: (−) Revolver Repayments | B8: 0 | C8: 0 | D8: 0 | E8: 0 | F8: 0 | G8: 0
A9: Revolver – Ending Balance | B9: 0 | C9: =MAX(0,C6+C7+C8) -> 0 | D9: =MAX(0,D6+D7+D8) -> 0 | E9: =MAX(0,E6+E7+E8) -> 0 | F9: =MAX(0,F6+F7+F8) -> 0 | G9: =MAX(0,G6+G7+G8) -> 0
A10: Revolver – Interest Expense | B10: 0 | C10: =-AVERAGE(C6,C9)*'Transaction Assumptions'!C40 -> 0 | D10: =-AVERAGE(D6,D9)*'Transaction Assumptions'!C40 -> 0 | E10: =-AVERAGE(E6,E9)*'Transaction Assumptions'!C40 -> 0 | F10: =-AVERAGE(F6,F9)*'Transaction Assumptions'!C40 -> 0 | G10: =-AVERAGE(G6,G9)*'Transaction Assumptions'!C40 -> 0
A11: ▌ TERM LOAN B
A12: Term Loan B – Beginning Balance | B12: ='Transaction Assumptions'!B41 -> 591302 | C12: ='Transaction Assumptions'!B41 -> 591302 | D12: =C15 -> 0 | E12: =D15 -> 0 | F12: =E15 -> 0 | G12: =F15 -> 0
A13: (−) Mandatory Amortization (5%) | B13: 0 | C13: =-'Transaction Assumptions'!B41*5% -> -29565.1 | D13: =-MIN(D12,'Transaction Assumptions'!$B$41*0.05) -> 0 | E13: =-MIN(E12,'Transaction Assumptions'!$B$41*0.05) -> 0 | F13: =-MIN(F12,'Transaction Assumptions'!$B$41*0.05) -> 0 | G13: =-MIN(G12,'Transaction Assumptions'!$B$41*0.05) -> 0
A14: (−) Optional Cash Sweep | B14: 0 | C14: =-MIN(C12+C13,MAX(0,C28+C29+C33)) -> -561736.9 | D14: =-MIN(D12+D13,MAX(0,D28+D29+D33)) -> 0 | E14: =-MIN(E12+E13,MAX(0,E28+E29+E33)) -> 0 | F14: =-MIN(F12+F13,MAX(0,F28+F29+F33)) -> 0 | G14: =-MIN(G12+G13,MAX(0,G28+G29+G33)) -> 0
A15: Term Loan B – Ending Balance | B15: =B12 -> 591302 | C15: =SUM(C12:C14) -> 0 | D15: =SUM(D12:D14) -> 0 | E15: =SUM(E12:E14) -> 0 | F15: =SUM(F12:F14) -> 0 | G15: =SUM(G12:G14) -> 0
A16: Term Loan B – Interest Expense | B16: 0 | C16: =AVERAGE(C12,C15)*'Transaction Assumptions'!C41 -> 22528.606 | D16: =AVERAGE(D12,D15)*'Transaction Assumptions'!C41 -> 0 | E16: =AVERAGE(E12,E15)*'Transaction Assumptions'!C41 -> 0 | F16: =AVERAGE(F12,F15)*'Transaction Assumptions'!C41 -> 0 | G16: =AVERAGE(G12,G15)*'Transaction Assumptions'!C41 -> 0
A17: ▌ PIK LOAN (Payment-in-Kind)
A18: PIK Loan – Beginning Balance | B18: ='Transaction Assumptions'!B42 -> 886953 | C18: ='Transaction Assumptions'!B42 -> 886953 | D18: =C20 -> 987799.56 | E18: =D20 -> 1100112.4 | F18: =E20 -> 1225195.1 | G18: =F20 -> 1364499.8
A19: (+) PIK Interest Accrual | B19: 0 | C19: =C18*'Transaction Assumptions'!C42 -> 100846.56 | D19: =D18*'Transaction Assumptions'!C42 -> 112312.81 | E19: =E18*'Transaction Assumptions'!C42 -> 125082.78 | F19: =F18*'Transaction Assumptions'!C42 -> 139304.69 | G19: =G18*'Transaction Assumptions'!C42 -> 155143.63
A20: PIK Loan – Ending Balance (incl. accrued PIK) | B20: =SUM(B18:B19) -> 886953 | C20: =C18+C19 -> 987799.56 | D20: =D18+D19 -> 1100112.4 | E20: =E18+E19 -> 1225195.1 | F20: =F18+F19 -> 1364499.8 | G20: =G18+G19 -> 1519643.5
A21: ▌ TOTAL DEBT & LEVERAGE
A22: Total Debt (Ending) | B22: ='Transaction Assumptions'!B41+'Transaction Assumptions'!B42 -> 1478255 | C22: =C9+C15+C20 -> 987799.56 | D22: =D9+D15+D20 -> 1100112.4 | E22: =E9+E15+E20 -> 1225195.1 | F22: =F9+F15+F20 -> 1364499.8 | G22: =G9+G15+G20 -> 1519643.5
A23: EBITDA (from LFCF sheet) | B23: ='Levered FCFs'!F18 -> 295651 | C23: ='Levered FCFs'!G18 -> 372712.24 | D23: ='Levered FCFs'!H18 -> 417437.71 | E23: ='Levered FCFs'!I18 -> 467530.23 | F23: ='Levered FCFs'!J18 -> 523633.86 | G23: ='Levered FCFs'!K18 -> 586469.92
A24: Total Leverage (x) | B24: =B22/B23 -> 5 | C24: =C22/C23 -> 2.6503008 | D24: =D22/D23 -> 2.6353929 | E24: =E22/E23 -> 2.6205688 | F24: =F22/F23 -> 2.6058281 | G24: =G22/G23 -> 2.5911703
A25: Max Leverage Covenant | B25: ='Transaction Assumptions'!B44 -> 7 | C25: ='Transaction Assumptions'!B44 -> 7 | D25: ='Transaction Assumptions'!B44 -> 7 | E25: ='Transaction Assumptions'!B44 -> 7 | F25: ='Transaction Assumptions'!B44 -> 7 | G25: ='Transaction Assumptions'!B44 -> 7
A26: Covenant Breach (TRUE = Breach) | B26: =IF(B24>B25,"BREACH","OK") -> OK | C26: =IF(C24>C25,"BREACH","OK") -> OK | D26: =IF(D24>D25,"BREACH","OK") -> OK | E26: =IF(E24>E25,"BREACH","OK") -> OK | F26: =IF(F24>F25,"BREACH","OK") -> OK | G26: =IF(G24>G25,"BREACH","OK") -> OK
A27: ▌ CASH SCHEDULE
A28: Cash – Beginning Balance | B28: ='Transaction Assumptions'!B11 -> 709171 | C28: =B34 -> 709171 | D28: =C34 -> 469151.24 | E28: =D34 -> 893540.58 | F28: =E34 -> 1382558.6 | G28: =F34 -> 1936899.9
A29: (+) Levered Free Cash Flow | B29: 0 | C29: ='Levered FCFs'!G31 -> 321717.14 | D29: ='Levered FCFs'!H31 -> 424389.35 | E29: ='Levered FCFs'!I31 -> 489017.97 | F29: ='Levered FCFs'!J31 -> 554341.34 | G29: ='Levered FCFs'!K31 -> 627752.27
A30: (+) BB of Cash | B30: 0 | C30: =C28 -> 709171 | D30: =D28 -> 469151.24 | E30: =E28 -> 893540.58 | F30: =F28 -> 1382558.6 | G30: =G28 -> 1936899.9
A31: (+) Net Revolver Activity | B31: 0 | C31: =C7+C8 -> 0 | D31: =D7+D8 -> 0 | E31: =E7+E8 -> 0 | F31: =F7+F8 -> 0 | G31: =G7+G8 -> 0
A32: (−) Optional Cash Sweep (TL) | B32: 0 | C32: =C14 -> -561736.9 | D32: =D14 -> 0 | E32: =E14 -> 0 | F32: =F14 -> 0 | G32: =G14 -> 0
A33: (−) Less Min Balance of Cash | B33: =-'Transaction Assumptions'!E21 -> -40000 | C33: =B33 -> -40000 | D33: =C33 -> -40000 | E33: =D33 -> -40000 | F33: =E33 -> -40000 | G33: =F33 -> -40000
A34: Cash – Ending Balance | B34: =B28 -> 709171 | C34: =MAX('Transaction Assumptions'!B43,C28+'Levered FCFs'!G31+C32) -> 469151.24 | D34: =MAX('Transaction Assumptions'!C43,D28+'Levered FCFs'!H31+D32) -> 893540.58 | E34: =MAX('Transaction Assumptions'!D43,E28+'Levered FCFs'!I31+E32) -> 1382558.6 | F34: =MAX('Transaction Assumptions'!E43,F28+'Levered FCFs'!J31+F32) -> 1936899.9 | G34: =MAX('Transaction Assumptions'!F43,G28+'Levered FCFs'!K31+G32) -> 2564652.2
A35: Net Debt (Ending) | B35: =B22-B34 -> 769084 | C35: =C22-C34 -> 518648.32 | D35: =D22-D34 -> 206571.78 | E35: =E22-E34 -> -157363.42 | F35: =F22-F34 -> -572400.07 | G35: =G22-G34 -> -1045008.7
A36: ▌ INTEREST EXPENSE SUMMARY
A37: Total Cash Interest Expense | B37: 0 | C37: =C10+C16 -> 22528.606 | D37: =D10+D16 -> 0 | E37: =E10+E16 -> 0 | F37: =F10+F16 -> 0 | G37: =G10+G16 -> 0
A38: PIK Interest (non-cash) | B38: 0 | C38: =C19 -> 100846.56 | D38: =D19 -> 112312.81 | E38: =E19 -> 125082.78 | F38: =F19 -> 139304.69 | G38: =G19 -> 155143.63
A39: Total Interest (Cash + PIK) | B39: 0 | C39: =C37+C38 -> 123375.16 | D39: =D37+D38 -> 112312.81 | E39: =E37+E38 -> 125082.78 | F39: =F37+F38 -> 139304.69 | G39: =G37+G38 -> 155143.63

Sheet Returns Analysis
A1: CPRX – Returns Analysis | MOIC & IRR
A2: All figures in $000s | 5-Year Hold (2025–2030)
A4: ▌ EXIT VALUATION (Base Case)
D5: Bear | E5: Base | F5: Bull
A6: Exit Multiple (x EV/EBITDA) | D6: ='Transaction Assumptions'!B49 -> 10 | E6: ='Transaction Assumptions'!C49 -> 12 | F6: ='Transaction Assumptions'!D49 -> 14
A7: Exit Year EBITDA ($000) | D7: ='Levered FCFs'!K18 -> 586469.92 | E7: ='Levered FCFs'!K18 -> 586469.92 | F7: ='Levered FCFs'!K18 -> 586469.92
A8: Enterprise Value at Exit ($000) | D8: =D6*D7 -> 5864699.2 | E8: =E6*E7 -> 7037639.1 | F8: =F6*F7 -> 8210578.9
A9: (−) Net Debt at Exit ($000) | D9: ='Capital Structure'!G35 -> -1045008.7 | E9: ='Capital Structure'!G35 -> -1045008.7 | F9: ='Capital Structure'!G35 -> -1045008.7
A10: Equity Value at Exit ($000) | D10: =D8-D9 -> 6909707.9 | E10: =E8-E9 -> 8082647.8 | F10: =F8-F9 -> 9255587.6
A11: ▌ SPONSOR EQUITY ANALYSIS
D12: Bear | E12: Base | F12: Bull
A13: Initial Equity Investment ($000) | D13: ='Transaction Assumptions'!B23 -> 664262.95 | E13: ='Transaction Assumptions'!B23 -> 664262.95 | F13: ='Transaction Assumptions'!B23 -> 664262.95
A14: Equity Proceeds at Exit ($000) | D14: =D10 -> 6909707.9 | E14: =E10 -> 8082647.8 | F14: =F10 -> 9255587.6
A15: MOIC (Money-on-Invested-Capital) | D15: =D14/D13 -> 10.402067 | E15: =E14/E13 -> 12.167844 | F15: =F14/F13 -> 13.93362
A16: IRR (Internal Rate of Return) | D16: =IRR(D54:D59,0) -> 0.59743771 | E16: =IRR(E54:E59,0) -> 0.64832454 | F16: =IRR(F54:F59,0) -> 0.6936076
A17: Hold Period (Years) | D17: 5 | E17: 5 | F17: 5
A19: ▌ MOIC SENSITIVITY TABLE (Exit Multiple vs Revenue Growth) | K19: BASE CASE DATA TABLE INPUT
A20: =E15 -> 12.167844 | B20: =C20-0.02 -> 0.04 | C20: =D20-0.02 -> 0.06 | D20: =E20-0.02 -> 0.08 | E20: =$F$20-0.02 -> 0.1 | F20: ='Transaction Assumptions'!B28 -> 0.12 | G20: =$F$20+0.02 -> 0.14 | H20: =G20+0.02 -> 0.16 | I20: =H20+0.02 -> 0.18 | K20: REVENUE GROWTH | L20: IRR | M20: MOIC
A21: 8 | B21: 5.8688634 | C21: 6.49037 | D21: 7.1570899 | E21: 7.8715303 | F21: 8.6362909 | G21: 9.4540652 | H21: 10.327643 | I21: 11.259909 | K21: ='Transaction Assumptions'!B28 -> 0.12 | L21: =IRR(E54:E59,0) -> 0.64832454 | M21: =E15 -> 12.167844
A22: 9 | B22: 6.4783755 | C22: 7.1607868 | D22: 7.8931857 | E22: 8.6783548 | F22: 9.5191792 | G22: 10.418649 | H22: 11.37986 | I22: 12.406018
A23: 10 | B23: 7.0878875 | C23: 7.8312037 | D23: 8.6292816 | E23: 9.4851792 | F23: 10.402067 | G23: 11.383232 | H23: 12.432078 | I23: 13.552126
A24: 11 | B24: 7.6973996 | C24: 8.5016205 | D24: 9.3653775 | E24: 10.292004 | F24: 11.284956 | G24: 12.347816 | H24: 13.484295 | I24: 14.698234
A25: 12 | B25: 8.3069116 | C25: 9.1720374 | D25: 10.101473 | E25: 11.098828 | F25: 12.167844 | G25: 13.3124 | H25: 14.536513 | I25: 15.844342
A26: 13 | B26: 8.9164237 | C26: 9.8424543 | D26: 10.837569 | E26: 11.905652 | F26: 13.050732 | G26: 14.276983 | H26: 15.58873 | I26: 16.990451
A27: 14 | B27: 9.5259357 | C27: 10.512871 | D27: 11.573665 | E27: 12.712477 | F27: 13.93362 | G27: 15.241567 | H27: 16.640948 | I27: 18.136559
A29: ▌ IRR SENSITIVITY TABLE (Exit Multiple vs Revenue Growth)
A30: =E16 -> 0.64832454 | B30: =C30-0.02 -> 0.04 | C30: =D30-0.02 -> 0.06 | D30: =E30-0.02 -> 0.08 | E30: =$F$30-0.02 -> 0.1 | F30: ='Transaction Assumptions'!B28 -> 0.12 | G30: =$F$30+0.02 -> 0.14 | H30: =G30+0.02 -> 0.16 | I30: =H30+0.02 -> 0.18
A31: 8 | B31: 0.42465859 | C31: 0.45363004 | D31: 0.48233818 | E31: 0.5108169 | F31: 0.53909509 | G31: 0.56719746 | H31: 0.59514527 | I31: 0.62295687
A32: 9 | B32: 0.45309237 | C32: 0.48249128 | D32: 0.51164727 | E32: 0.54059144 | F32: 0.56935032 | G32: 0.59794667 | H32: 0.62640007 | I32: 0.65472748
A33: 10 | B33: 0.47946046 | C33: 0.50926571 | D33: 0.53884518 | E33: 0.56822765 | F33: 0.59743771 | G33: 0.62649645 | H33: 0.65542208 | I33: 0.68423034
A34: 11 | B34: 0.50407262 | C34: 0.53426488 | D34: 0.56424601 | E34: 0.59404283 | F34: 0.62367824 | G34: 0.65317196 | H34: 0.68254098 | I34: 0.71180004
A35: 12 | B35: 0.52717188 | C35: 0.55773351 | D35: 0.5880967 | E35: 0.61828655 | F35: 0.64832454 | G35: 0.67822918 | H35: 0.70801644 | I35: 0.73770017
A36: 13 | B36: 0.54895264 | C36: 0.57986756 | D36: 0.61059511 | E36: 0.64115893 | F36: 0.67157926 | G36: 0.70187355 | H36: 0.73205688 | I36: 0.76214231
A37: 14 | B37: 0.56957304 | C37: 0.60082651 | D37: 0.6319024 | E37: 0.66282304 | F37: 0.6936076 | G37: 0.72427258 | H37: 0.75483227 | I37: 0.78529907
A54: IRR Helper (year 0) | D54: =-D13 -> -664262.95 | E54: =-E13 -> -664262.95 | F54: =-F13 -> -664262.95
A55: IRR Helper (years 1-4) | D55: 0 | E55: 0 | F55: 0
A56: IRR Helper (year 5) | D56: 0 | E56: 0 | F56: 0
D57: 0 | E57: 0 | F57: 0
D58: 0 | E58: 0 | F58: 0
D59: =D14 -> 6909707.9 | E59: =E14 -> 8082647.8 | F59: =F14 -> 9255587.6
...

Sheet Value Creation
A1: CPRX – Value Creation Reconciliation & Equity Waterfall
A2: All figures in $000s | Bridges Entry EV → Exit EV → Equity Returns
A4: ▌ VALUE CREATION BRIDGE
A5: Component | B5: Amount ($000) | C5: % of Total Value Created | D5: Notes
A6: Entry Enterprise Value | B6: ='Transaction Assumptions'!B10 -> 2793901.9 | D6: Entry EV = EBITDA × Entry Multiple
A7: Exit Enterprise Value (Base Case) | B7: ='Returns Analysis'!E8 -> 7037639.1 | D7: Exit EV = Exit EBITDA × Exit Multiple
A8: Total Value Created | B8: =B7-B6 -> 4243737.1
A10: ▌ VALUE CREATION ATTRIBUTION
A11: Driver | B11: Value ($000) | C11: % Contribution | D11: Description
A12: ① EBITDA Growth | B12: =('Returns Analysis'!E7-'Transaction Assumptions'!B7)*'Transaction Assumptions'!B9 -> 2748238.8 | C12: =IFERROR(B12/B15,0) -> 0.45366722 | D12: Organic top-line & margin expansion
A13: ② Multiple Expansion / (Compression) | B13: =('Returns Analysis'!E6-'Transaction Assumptions'!B9)*'Returns Analysis'!E7 -> 1495498.3 | C13: =IFERROR(B13/B15,0) -> 0.24687031 | D13: Exit multiple vs entry multiple on exit EBITDA
A14: ③ Debt Paydown (Deleveraging) | B14: =('Transaction Assumptions'!B21+'Transaction Assumptions'!B22-'Transaction Assumptions'!B20)-('Capital Structure'!G15+'Capital Structure'!G20-'Capital Structure'!G34) -> 1814092.7 | C14: =IFERROR(B14/B15,0) -> 0.29946247 | D14: FCF and Cash used to repay debt; reduces EV capture by lenders [NET DEBT]
A15: Total Value Created (Check) | B15: =B12+B13+B14 -> 6057829.8 | C15: =IFERROR(B15/B15,0) -> 1
A17: ▌ EQUITY WATERFALL DISTRIBUTION (Base Case)
A18: Distribution Tier | B18: Amount ($000) | C18: Cumulative ($000) | D18: Description
A19: Total Exit Enterprise Value | B19: ='Returns Analysis'!E8 -> 7037639.1 | C19: =B19 -> 7037639.1 | D19: EV at exit
A20: (−) Revolver Repayment | B20: 0 | C20: =B19-B20 -> 7037639.1 | D20: Senior secured; repaid first
A21: (−) Term Loan B Repayment | B21: =-('Capital Structure'!G15) -> 0 | C21: =C20+B21 -> 7037639.1 | D21: First lien term loan
A22: (−) PIK Loan Repayment (incl. accrued interest) | B22: =-('Capital Structure'!G20) -> -1519643.5 | C22: =C21+B22 -> 5517995.6 | D22: Includes 5Y PIK accrual
A23: (+) Total Cash at Exit | B23: ='Capital Structure'!G34 -> 2564652.2 | C23: =B23+C22 -> 8082647.8
A24: Remaining Value to Equity | B24: =B19+B20+B21+B22+B23 -> 8082647.8 | C24: =C23 -> 8082647.8 | D24: Post-debt proceeds
A25: FLOOR Test (Min. Equity) | B25: =-MAX(0,'Transaction Assumptions'!B23*((1+0.08)^5)) -> -976020.2 | C25: =C24+B25 -> 7106627.6 | D25: 8% IRR floor protection
A26: Sponsor Equity Return (above FLOOR) | B26: =MAX(0,B24+B25) -> 7106627.6 | C26: =C25 -> 7106627.6 | D26: Sponsor captures residual
A27: Management / Co-Investors (est. 10%) | B27: =-B26*0.1 -> -710662.76 | C27: =C26+B27 -> 6395964.8 | D27: Carried interest / mgmt pool
A28: Sponsor Net Equity Proceeds | B28: =B26+B27 -> 6395964.8 | C28: =B28 -> 6395964.8 | D28: Base case sponsor return
A30: ▌ EQUITY RETURN SUMMARY
A31: Initial Equity Investment | B31: ='Transaction Assumptions'!B23 -> 664262.95
A32: Equity Proceeds (Base) | B32: ='Returns Analysis'!E10 -> 8082647.8
A33: MOIC (Base Case) | B33: ='Returns Analysis'!E15 -> 12.167844
A34: IRR (Base Case) | B34: ='Returns Analysis'!E16 -> 0.64832454
A35: MOIC (Bear Case) | B35: ='Returns Analysis'!D15 -> 10.402067
A36: IRR (Bear Case) | B36: ='Returns Analysis'!D16 -> 0.59743771
A37: MOIC (Bull Case) | B37: ='Returns Analysis'!F15 -> 13.93362
A38: IRR (Bull Case) | B38: ='Returns Analysis'!F16 -> 0.6936076
